[2020-07-13 23:07:34,100] {taskinstance.py:669} INFO - Dependencies all met for <TaskInstance: news_fetch.push_s3 2020-07-11T01:01:00+00:00 [queued]>
[2020-07-13 23:07:34,111] {taskinstance.py:669} INFO - Dependencies all met for <TaskInstance: news_fetch.push_s3 2020-07-11T01:01:00+00:00 [queued]>
[2020-07-13 23:07:34,112] {taskinstance.py:879} INFO - 
--------------------------------------------------------------------------------
[2020-07-13 23:07:34,112] {taskinstance.py:880} INFO - Starting attempt 1 of 2
[2020-07-13 23:07:34,112] {taskinstance.py:881} INFO - 
--------------------------------------------------------------------------------
[2020-07-13 23:07:34,118] {taskinstance.py:900} INFO - Executing <Task(PythonOperator): push_s3> on 2020-07-11T01:01:00+00:00
[2020-07-13 23:07:34,120] {standard_task_runner.py:53} INFO - Started process 25336 to run task
[2020-07-13 23:07:34,150] {logging_mixin.py:112} INFO - Running %s on host %s <TaskInstance: news_fetch.push_s3 2020-07-11T01:01:00+00:00 [running]> tony-ThinkPad-X1-Carbon-7th
[2020-07-13 23:07:34,158] {taskinstance.py:1145} ERROR - upload_file() got an unexpected keyword argument 'filename'
Traceback (most recent call last):
  File "/home/tony/.virtualenvs/cv/lib/python3.6/site-packages/airflow/models/taskinstance.py", line 983, in _run_raw_task
    result = task_copy.execute(context=context)
  File "/home/tony/.virtualenvs/cv/lib/python3.6/site-packages/airflow/operators/python_operator.py", line 113, in execute
    return_value = self.execute_callable()
  File "/home/tony/.virtualenvs/cv/lib/python3.6/site-packages/airflow/operators/python_operator.py", line 118, in execute_callable
    return self.python_callable(*self.op_args, **self.op_kwargs)
TypeError: upload_file() got an unexpected keyword argument 'filename'
[2020-07-13 23:07:34,159] {taskinstance.py:1168} INFO - Marking task as UP_FOR_RETRY
[2020-07-13 23:07:44,097] {logging_mixin.py:112} INFO - [2020-07-13 23:07:44,096] {local_task_job.py:103} INFO - Task exited with return code 1
