[2020-07-13 22:34:04,237] {taskinstance.py:669} INFO - Dependencies all met for <TaskInstance: news_fetch.push_s3 2020-07-11T00:05:00+00:00 [queued]>
[2020-07-13 22:34:04,248] {taskinstance.py:669} INFO - Dependencies all met for <TaskInstance: news_fetch.push_s3 2020-07-11T00:05:00+00:00 [queued]>
[2020-07-13 22:34:04,248] {taskinstance.py:879} INFO - 
--------------------------------------------------------------------------------
[2020-07-13 22:34:04,248] {taskinstance.py:880} INFO - Starting attempt 2 of 2
[2020-07-13 22:34:04,248] {taskinstance.py:881} INFO - 
--------------------------------------------------------------------------------
[2020-07-13 22:34:04,258] {taskinstance.py:900} INFO - Executing <Task(PythonOperator): push_s3> on 2020-07-11T00:05:00+00:00
[2020-07-13 22:34:04,261] {standard_task_runner.py:53} INFO - Started process 18658 to run task
[2020-07-13 22:34:04,301] {logging_mixin.py:112} INFO - Running %s on host %s <TaskInstance: news_fetch.push_s3 2020-07-11T00:05:00+00:00 [running]> tony-ThinkPad-X1-Carbon-7th
[2020-07-13 22:34:04,312] {taskinstance.py:1145} ERROR - upload_file() got an unexpected keyword argument 'filename'
Traceback (most recent call last):
  File "/home/tony/.virtualenvs/cv/lib/python3.6/site-packages/airflow/models/taskinstance.py", line 983, in _run_raw_task
    result = task_copy.execute(context=context)
  File "/home/tony/.virtualenvs/cv/lib/python3.6/site-packages/airflow/operators/python_operator.py", line 113, in execute
    return_value = self.execute_callable()
  File "/home/tony/.virtualenvs/cv/lib/python3.6/site-packages/airflow/operators/python_operator.py", line 118, in execute_callable
    return self.python_callable(*self.op_args, **self.op_kwargs)
TypeError: upload_file() got an unexpected keyword argument 'filename'
[2020-07-13 22:34:04,313] {taskinstance.py:1187} INFO - All retries failed; marking task as FAILED.dag_id=news_fetch, task_id=push_s3, execution_date=20200711T000500, start_date=20200713T143404, end_date=20200713T143404
[2020-07-13 22:34:14,233] {logging_mixin.py:112} INFO - [2020-07-13 22:34:14,233] {local_task_job.py:103} INFO - Task exited with return code 1
